Workbook

Sheet Rechnung
A1: Stromkosten - Mai 2026
A2: Rechnungsansicht / Offline-Nachrechnung, keine offizielle Rechnung. Blau markierte Eingaben sind im Blatt Eingaben aenderbar. Die gelieferte CSV wird ohne Kontonummer weiterverarbeitet.
A5: Datenbasis | B5: =Eingaben!B5 -> Report
A6: Vollstaendigkeit | B6: =Tageswerte!B39 -> OK
A7: Position | B7: Menge | C7: Preis / Basis | D7: Betrag brutto
A8: Stromverbrauch GO | B8: =Tageswerte!M39 -> 3.199 | C8: =IF(ISNUMBER(Eingaben!B11),Eingaben!B11,"nicht belegt") -> 15.0654 | D8: =IF(Tageswerte!$B$39<>"OK","",Tageswerte!S39) -> 0.48194215
A9: Stromverbrauch STANDARD | B9: =Tageswerte!N39 -> 9.197 | C9: =IF(ISNUMBER(Eingaben!B12),Eingaben!B12,"nicht belegt") -> 28.2744 | D9: =IF(Tageswerte!$B$39<>"OK","",Tageswerte!T39) -> 2.6003966
A10: Stromverbrauch HEAT (optional) | B10: =Tageswerte!O39 -> 0 | C10: =IF(ISNUMBER(Eingaben!B13),Eingaben!B13,"nicht belegt") -> nicht belegt | D10: =IF(Tageswerte!$B$39<>"OK","",Tageswerte!U39) -> 0
A11: Gesamtverbrauch | B11: =Tageswerte!L39 -> 12.396
A13: Grundgebuehr fuer den Monat | C13: =Eingaben!B15 -> Zeitanteilig | D13: =IF(Tageswerte!$B$39<>"OK","",Tageswerte!V39) -> 18.089239
A14: Anpassung Vertragsnetz an Vergleichsnetz | C14: =Eingaben!B6 -> Vertragsstart | D14: =IF(Tageswerte!$B$39<>"OK","",Tageswerte!W39) -> 0
A15: Zwischensumme vor Modulen | D15: =IF(Tageswerte!$B$39<>"OK","",SUM(D8:D10,D13:D14)) -> 21.171578
A17: Abzueglich Modul 1 - pauschale Gutschrift | D17: =IF(Tageswerte!$B$39<>"OK","",Tageswerte!X39) -> -10.94875
A18: Abzueglich Modul 3 - Nettoeffekt NT/ST/HT | D18: =IF(Tageswerte!$B$39<>"OK","",-Tageswerte!AC39) -> -0.35122374
A20: GESAMTKOSTEN DES MONATS | D20: =IF(Tageswerte!$B$39<>"OK","",D15+D17+D18) -> 9.871604
A22: Monatssumme im gelieferten CSV | D22: 9.87
A23: Differenz Nachrechnung minus CSV | D23: =IF(Tageswerte!$B$39<>"OK","",D20-D22) -> 0.0016040151
A24: Rundung: die CSV enthaelt bereits gerundete Mengen und Centbetraege. Excel rechnet ungerundet bis zur Anzeige. Im Ausgangsbeispiel stimmt die Monatssumme auf Cent. Tagescentwerte muessen nicht auf die Monatssumme addieren.
A27: Modul 3 ausgeschrieben - so wird das Netzentgelt ausgetauscht
A28: Rechenschritt | B28: Menge | C28: Brutto ct/kWh | D28: Betrag
A29: Vergleichs-Netzentgelt abziehen | B29: =Tageswerte!L39 -> 12.396 | C29: =IF(ISNUMBER(Eingaben!B10),Eingaben!B10*(1+Eingaben!B7),"") -> 9.1035 | D29: =IF(Tageswerte!$B$39<>"OK","",Tageswerte!Y39) -> -1.1284699
A30: Netzentgelt NT hinzufuegen | B30: =Tageswerte!P39 -> 4.78 | C30: =IF(OR(B30="",B30=0),"",D30/B30*100) -> 1.9516 | D30: =IF(Tageswerte!$B$39<>"OK","",Tageswerte!Z39) -> 0.09328648
A31: Netzentgelt ST hinzufuegen | B31: =Tageswerte!Q39 -> 4.493 | C31: =IF(OR(B31="",B31=0),"",D31/B31*100) -> 6.5212 | D31: =IF(Tageswerte!$B$39<>"OK","",Tageswerte!AA39) -> 0.29299752
A32: Netzentgelt HT hinzufuegen | B32: =Tageswerte!R39 -> 3.123 | C32: =IF(OR(B32="",B32=0),"",D32/B32*100) -> 12.5188 | D32: =IF(Tageswerte!$B$39<>"OK","",Tageswerte!AB39) -> 0.39096212
A34: Nettoeffekt des Austauschs (bereits oben) | D34: =IF(Tageswerte!$B$39<>"OK","",SUM(D29:D32)) -> -0.35122374
A35: Negative Differenz = Einsparung, positive Differenz = Mehrkosten. Die Detailpositionen 29-32 werden NICHT noch einmal auf die Rechnung addiert. Bei Vergleich aktuelles Jahr gleicht Position 14 zuerst das im Vertrags-AP enthaltene Netzentgelt an. So bleibt der Endbetrag bei gleicher NT/ST/HT-Bepreisung unabhaengig von der gewaehlten Vergleichsbasis.
A39: Modul 1 - Jahresgutschrift netto | D39: =Eingaben!B16 -> 108.33
A40: Modul 1 - Jahresgutschrift brutto | D40: =Eingaben!B16*(1+Eingaben!B7) -> 128.9127
A41: Modul 1 - Monatsanteil brutto | D41: =IF(Tageswerte!$B$39<>"OK","",-Tageswerte!X39) -> 10.94875
A43: Viertelstundenmodus: Erst 96 Werte pro Tag eintragen, individuelle Tarif-Slots bei Bedarf im Blatt Intervalle setzen, danach den Datenmodus umstellen. Fehlende Werte sperren die Monatsrechnung. Tarifpreise und Modul-1-/Modul-3-Eingaben werden ohne Home Assistant, API, Makros oder Python in Excel neu berechnet.

Sheet Eingaben
A1: Eingaben und Rechenbasis
A2: Blau = editierbar. Alle Endbetraege brutto. Netzentgelte und Modul-1-Jahresbetrag werden netto eingegeben. Das Beispiel ist eine Kostensimulation, keine Lieferantenrechnung.
A5: Datenmodus | B5: Report | C5: Report = echte Tagesaggregate der CSV; Viertelstunden = ausschliesslich eigene 96-Werte-Eingaben.
A6: Vergleich Modul 3 | B6: Vertragsstart | C6: Aktuelles Jahr erfordert B9. Das ST-Band ist NICHT automatisch das normale Standard-Netzentgelt.
A7: Umsatzsteuer | B7: 0.19 | C7: Aus BASIS: 19 %.
A8: Netzentgelt im Vertrags-AP (netto ct/kWh) | B8: 7.65 | C8: Vertragsstart: 7,65 ct/kWh. Wird nicht erneut auf den Vertrags-AP addiert.
A9: Normales Netzentgelt aktuelles Jahr (netto ct/kWh) | C9: NICHT im Report separat belegt. Vor Vergleich 'Aktuelles Jahr' hier eintragen.
A10: Gewaehlte Vergleichsrate netto ct/kWh | B10: =IF(B6="Vertragsstart",B8,IF(ISNUMBER(B9),B9,"")) -> 7.65
A11: GO Arbeitspreis (brutto ct/kWh) | B11: 15.0654 | C11: Mai-Vertrag aus BASIS, nicht der erst ab September gueltige Vertrag.
A12: STANDARD Arbeitspreis (brutto ct/kWh) | B12: 28.2744 | C12: STANDARD bezeichnet den Stromtarif, ST bezeichnet das Netzzeitband.
A13: HEAT Arbeitspreis (brutto ct/kWh) | C13: Optional. Im gelieferten Report kein HEAT-Verbrauch. Bei HEAT-Menge ist der Preis Pflicht.
A14: Vertragliche Grundgebuehr (brutto EUR/Monat) | B14: 17.74885 | C14: 17,74885 EUR; im vorhandenen Report auf Jahresbasis zeitanteilig verrechnet.
A15: Grundgebuehr-Verrechnung | B15: Zeitanteilig | C15: Zeitanteilig: Monatsbetrag x 12 / 365 je Tag; Pauschal: Monatsbetrag / Monatstage. Bewusste Szenarioaenderung.
A16: Modul 1 Gutschrift (netto EUR/Jahr) | B16: 108.33 | C16: Aus BASIS: 108,33 EUR. Anteil ab Wirksamkeitsdatum / Kalendertage des Jahres, danach USt.
A17: Modul 1 wirksam ab | B17: 45352 | C17: Kein Bezug zu NT/ST/HT: Modul 1 ist eine zeitanteilige pauschale Gutschrift.
A18: Modul 3 wirksam ab | B18: 45748 | C18: Vorher normales Netzentgelt verwenden; dafuer ist B9 erforderlich.
A19: Abrechnungsjahr | B19: 2026 | C19: Prototyp fest Mai 2026; Datumseingaben nicht auf einen anderen Monat umstellen.
A20: Abrechnungsmonat | B20: 5 | C20: Produktive Version erzeugt passende Tabellen fuer jeden Monat.
A21: GO Zeitfenster von | B21: 0 | C21: 00:00 bis 05:00 aus Mai-Vertrag. Individuelle Intelligent-GO-Slots haben im Blatt Intervalle Vorrang.
A22: GO Zeitfenster bis (exklusiv) | B22: 0.20833333 | C22: Tarif und Netzband sind unabhaengige Zuordnungen.
A23: Optionales HEAT Zeitfenster von | C23: Nur im Viertelstundenmodus. Beide Zeiten und HEAT-Preis setzen; individuelles Override hat Vorrang.
A24: Optionales HEAT Zeitfenster bis | C24: HEAT wird im Prototyp nach GO geprueft. Produktionsversion uebernimmt echte Vertragsregeln.
A25: Kalendertage des Monats | B25: =DAY(DATE(B19,B20+1,0)) -> 31
A26: Kalendertage des Jahres | B26: =DATE(B19+1,1,1)-DATE(B19,1,1) -> 365
A27: Vergleichsrate Status | B27: =IF(ISNUMBER(B10),"OK","NETZREFERENZ FEHLT") -> OK
A28: Netzbetreiber | B28: EAM Netz GmbH | C28: API bezeichnet MODULE_1, liefert aber variable NT/ST/HT-Raten. Explizites Modul-3-Datum ist gesetzt.
A30: Modul 3 NT (netto ct/kWh) | B30: 1.64 | C30: OFFPEAK aus API. Stundenweise Overrides im Blatt Netzzeiten moeglich.
A31: Modul 3 ST (netto ct/kWh) | B31: 5.48 | C31: STANDARD aus variablem Netzzeitplan, kein belegter normaler Jahrestarif.
A32: Modul 3 HT (netto ct/kWh) | B32: 10.52 | C32: PEAK aus API.

Sheet Tageswerte
A1: Tagesmengen und Tagesrechnung
A2: Tarif x Netzband: zwei unabhaengige Dimensionen. Alle Tageskosten als Excel-Formeln. Leere/ungueltige Viertelstunden sperren die Monatsrechnung. Reportmodus verwendet echte Tagesmengen; er rekonstruiert keine Zeitreihe.
A5: Datum | B5: Berechnungsstatus | C5: GO NT kWh | D5: GO ST kWh | E5: GO HT kWh | F5: STANDARD NT kWh | G5: STANDARD ST kWh | H5: STANDARD HT kWh | I5: HEAT NT kWh | J5: HEAT ST kWh | K5: HEAT HT kWh | L5: Gesamt kWh | M5: GO kWh | N5: STANDARD kWh | O5: HEAT kWh | P5: NT kWh | Q5: ST kWh | R5: HT kWh | S5: GO Kosten EUR | T5: STANDARD Kosten EUR | U5: HEAT Kosten EUR | V5: Grundgebuehr EUR | W5: Referenzanpassung EUR | X5: Modul 1 Abzug EUR | Y5: Referenznetz entfernen EUR | Z5: NT Netz EUR | AA5: ST Netz EUR | AB5: HT Netz EUR | AC5: Modul 3 Einsparung EUR | AD5: Gesamt EUR | AE5: CSV Tag EUR | AF5: Differenz EUR
A6: 46143 | B6: =IF(Eingaben!$B$27<>"OK","NETZREFERENZ FEHLT",IF(AND(A6<Eingaben!$B$18,NOT(ISNUMBER(Eingaben!$B$9))),"NORMALER NETZPREIS FEHLT",IF(Eingaben!$B$5="Report",IF(Reportdaten!Q6<>"complete","REPORT UNVOLLSTAENDIG",IF(AND(SUM(Reportdaten!I6:K6)>0,NOT(ISNUMBER(Eingaben!$B$13))),"HEAT-PREIS FEHLT","OK")),IF(COUNTIF(Intervalle!J6:J101,"OK")=96,"OK","INTERVALLE UNVOLLSTAENDIG")))) -> OK | C6: =IF($B6<>"OK","",IF(Eingaben!$B$5="Report",Reportdaten!C6,SUMIFS(Intervalle!$C$6:$C$101,Intervalle!$F$6:$F$101,"GO",Intervalle!$G$6:$G$101,"NT"))) -> 0.22 | D6: =IF($B6<>"OK","",IF(Eingaben!$B$5="Report",Reportdaten!D6,SUMIFS(Intervalle!$C$6:$C$101,Intervalle!$F$6:$F$101,"GO",Intervalle!$G$6:$G$101,"ST"))) -> 0 | E6: =IF($B6<>"OK","",IF(Eingaben!$B$5="Report",Reportdaten!E6,SUMIFS(Intervalle!$C$6:$C$101,Intervalle!$F$6:$F$101,"GO",Intervalle!$G$6:$G$101,"HT"))) -> 0 | F6: =IF($B6<>"OK","",IF(Eingaben!$B$5="Report",Reportdaten!F6,SUMIFS(Intervalle!$C$6:$C$101,Intervalle!$F$6:$F$101,"STANDARD",Intervalle!$G$6:$G$101,"NT"))) -> 0.02 | G6: =IF($B6<>"OK","",IF(Eingaben!$B$5="Report",Reportdaten!G6,SUMIFS(Intervalle!$C$6:$C$101,Intervalle!$F$6:$F$101,"STANDARD",Intervalle!$G$6:$G$101,"ST"))) -> 0.086 | H6: =IF($B6<>"OK","",IF(Eingaben!$B$5="Report",Reportdaten!H6,SUMIFS(Intervalle!$C$6:$C$101,Intervalle!$F$6:$F$101,"STANDARD",Intervalle!$G$6:$G$101,"HT"))) -> 0.068 | I6: =IF($B6<>"OK","",IF(Eingaben!$B$5="Report",Reportdaten!I6,SUMIFS(Intervalle!$C$6:$C$101,Intervalle!$F$6:$F$101,"HEAT",Intervalle!$G$6:$G$101,"NT"))) -> 0 | J6: =IF($B6<>"OK","",IF(Eingaben!$B$5="Report",Reportdaten!J6,SUMIFS(Intervalle!$C$6:$C$101,Intervalle!$F$6:$F$101,"HEAT",Intervalle!$G$6:$G$101,"ST"))) -> 0 | K6: =IF($B6<>"OK","",IF(Eingaben!$B$5="Report",Reportdaten!K6,SUMIFS(Intervalle!$C$6:$C$101,Intervalle!$F$6:$F$101,"HEAT",Intervalle!$G$6:$G$101,"HT"))) -> 0 | L6: =IF($B6<>"OK","",SUM(C6:K6)) -> 0.394 | M6: =IF($B6<>"OK","",SUM(C6:E6)) -> 0.22 | N6: =IF($B6<>"OK","",SUM(F6:H6)) -> 0.174 | O6: =IF($B6<>"OK","",SUM(I6:K6)) -> 0 | P6: =IF($B6<>"OK","",C6+F6+I6) -> 0.24 | Q6: =IF($B6<>"OK","",D6+G6+J6) -> 0.086 | R6: =IF($B6<>"OK","",E6+H6+K6) -> 0.068 | S6: =IF($B6<>"OK","",M6*Eingaben!$B$11/100) -> 0.03314388 | T6: =IF($B6<>"OK","",N6*Eingaben!$B$12/100) -> 0.049197456 | U6: =IF($B6<>"OK","",IF(O6=0,0,O6*Eingaben!$B$13/100)) -> 0 | V6: =IF($B6<>"OK","",IF(Eingaben!$B$15="Zeitanteilig",Eingaben!$B$14*12/365,Eingaben!$B$14/Eingaben!$B$25)) -> 0.58352384 | W6: =IF($B6<>"OK","",L6*(IF(A6<Eingaben!$B$18,Eingaben!$B$9,Eingaben!$B$10)-Eingaben!$B$8)*(1+Eingaben!$B$7)/100) -> 0 | X6: =IF($B6<>"OK","",IF(A6>=Eingaben!$B$17,-Eingaben!$B$16*(1+Eingaben!$B$7)/Eingaben!$B$26,0)) -> -0.35318548 | Y6: =IF($B6<>"OK","",-L6*IF(A6<Eingaben!$B$18,Eingaben!$B$9,Eingaben!$B$10)*(1+Eingaben!$B$7)/100) -> -0.03586779 | Z6: =IF($B6<>"OK","",IF(A6<Eingaben!$B$18,P6*Eingaben!$B$9/100,IF(Eingaben!$B$5="Report",P6*Eingaben!$B$30/100,SUMIFS(Intervalle!$K$6:$K$101,Intervalle!$G$6:$G$101,"NT")))*(1+Eingaben!$B$7)) -> 0.00468384 | AA6: =IF($B6<>"OK","",IF(A6<Eingaben!$B$18,Q6*Eingaben!$B$9/100,IF(Eingaben!$B$5="Report",Q6*Eingaben!$B$31/100,SUMIFS(Intervalle!$K$6:$K$101,Intervalle!$G$6:$G$101,"ST")))*(1+Eingaben!$B$7)) -> 0.005608232 | AB6: =IF($B6<>"OK","",IF(A6<Eingaben!$B$18,R6*Eingaben!$B$9/100,IF(Eingaben!$B$5="Report",R6*Eingaben!$B$32/100,SUMIFS(Intervalle!$K$6:$K$101,Intervalle!$G$6:$G$101,"HT")))*(1+Eingaben!$B$7)) -> 0.008512784 | AC6: =IF($B6<>"OK","",-SUM(Y6:AB6)) -> 0.017062934 | AD6: =IF($B6<>"OK","",SUM(S6:AB6)) -> 0.29561676 | AE6: =IF($B6<>"OK","",IF(Eingaben!$B$5="Report",Reportdaten!L6,"")) -> 0.3 | AF6: =IF($B6<>"OK","",IF(Eingaben!$B$5="Report",AD6-AE6,"")) -> -0.0043832418
A7: 46144 | B7: =IF(Eingaben!$B$27<>"OK","NETZREFERENZ FEHLT",IF(AND(A7<Eingaben!$B$18,NOT(ISNUMBER(Eingaben!$B$9))),"NORMALER NETZPREIS FEHLT",IF(Eingaben!$B$5="Report",IF(Reportdaten!Q7<>"complete","REPORT UNVOLLSTAENDIG",IF(AND(SUM(Reportdaten!I7:K7)>0,NOT(ISNUMBER(Eingaben!$B$13))),"HEAT-PREIS FEHLT","OK")),IF(COUNTIF(Intervalle!J102:J197,"OK")=96,"OK","INTERVALLE UNVOLLSTAENDIG")))) -> OK | C7: =IF($B7<>"OK","",IF(Eingaben!$B$5="Report",Reportdaten!C7,SUMIFS(Intervalle!$C$102:$C$197,Intervalle!$F$102:$F$197,"GO",Intervalle!$G$102:$G$197,"NT"))) -> 0.06 | D7: =IF($B7<>"OK","",IF(Eingaben!$B$5="Report",Reportdaten!D7,SUMIFS(Intervalle!$C$102:$C$197,Intervalle!$F$102:$F$197,"GO",Intervalle!$G$102:$G$197,"ST"))) -> 0 | E7: =IF($B7<>"OK","",IF(Eingaben!$B$5="Report",Reportdaten!E7,SUMIFS(Intervalle!$C$102:$C$197,Intervalle!$F$102:$F$197,"GO",Intervalle!$G$102:$G$197,"HT"))) -> 0 | F7: =IF($B7<>"OK","",IF(Eingaben!$B$5="Report",Reportdaten!F7,SUMIFS(Intervalle!$C$102:$C$197,Intervalle!$F$102:$F$197,"STANDARD",Intervalle!$G$102:$G$197,"NT"))) -> 0.023 | G7: =IF($B7<>"OK","",IF(Eingaben!$B$5="Report",Reportdaten!G7,SUMIFS(Intervalle!$C$102:$C$197,Intervalle!$F$102:$F$197,"STANDARD",Intervalle!$G$102:$G$197,"ST"))) -> 0.061 | H7: =IF($B7<>"OK","",IF(Eingaben!$B$5="Report",Reportdaten!H7,SUMIFS(Intervalle!$C$102:$C$197,Intervalle!$F$102:$F$197,"STANDARD",Intervalle!$G$102:$G$197,"HT"))) -> 0.266 | I7: =IF($B7<>"OK","",IF(Eingaben!$B$5="Report",Reportdaten!I7,SUMIFS(Intervalle!$C$102:$C$197,Intervalle!$F$102:$F$197,"HEAT",Intervalle!$G$102:$G$197,"NT"))) -> 0 | J7: =IF($B7<>"OK","",IF(Eingaben!$B$5="Report",Reportdaten!J7,SUMIFS(Intervalle!$C$102:$C$197,Intervalle!$F$102:$F$197,"HEAT",Intervalle!$G$102:$G$197,"ST"))) -> 0 | K7: =IF($B7<>"OK","",IF(Eingaben!$B$5="Report",Reportdaten!K7,SUMIFS(Intervalle!$C$102:$C$197,Intervalle!$F$102:$F$197,"HEAT",Intervalle!$G$102:$G$197,"HT"))) -> 0 | L7: =IF($B7<>"OK","",SUM(C7:K7)) -> 0.41 | M7: =IF($B7<>"OK","",SUM(C7:E7)) -> 0.06 | N7: =IF($B7<>"OK","",SUM(F7:H7)) -> 0.35 | O7: =IF($B7<>"OK","",SUM(I7:K7)) -> 0 | P7: =IF($B7<>"OK","",C7+F7+I7) -> 0.083 | Q7: =IF($B7<>"OK","",D7+G7+J7) -> 0.061 | R7: =IF($B7<>"OK","",E7+H7+K7) -> 0.266 | S7: =IF($B7<>"OK","",M7*Eingaben!$B$11/100) -> 0.00903924 | T7: =IF($B7<>"OK","",N7*Eingaben!$B$12/100) -> 0.0989604 | U7: =IF($B7<>"OK","",IF(O7=0,0,O7*Eingaben!$B$13/100)) -> 0 | V7: =IF($B7<>"OK","",IF(Eingaben!$B$15="Zeitanteilig",Eingaben!$B$14*12/365,Eingaben!$B$14/Eingaben!$B$25)) -> 0.58352384 | W7: =IF($B7<>"OK","",L7*(IF(A7<Eingaben!$B$18,Eingaben!$B$9,Eingaben!$B$10)-Eingaben!$B$8)*(1+Eingaben!$B$7)/100) -> 0 | X7: =IF($B7<>"OK","",IF(A7>=Eingaben!$B$17,-Eingaben!$B$16*(1+Eingaben!$B$7)/Eingaben!$B$26,0)) -> -0.35318548 | Y7: =IF($B7<>"OK","",-L7*IF(A7<Eingaben!$B$18,Eingaben!$B$9,Eingaben!$B$10)*(1+Eingaben!$B$7)/100) -> -0.03732435 | Z7: =IF($B7<>"OK","",IF(A7<Eingaben!$B$18,P7*Eingaben!$B$9/100,IF(Eingaben!$B$5="Report",P7*Eingaben!$B$30/100,SUMIFS(Intervalle!$K$102:$K$197,Intervalle!$G$102:$G$197,"NT")))*(1+Eingaben!$B$7)) -> 0.001619828 | AA7: =IF($B7<>"OK","",IF(A7<Eingaben!$B$18,Q7*Eingaben!$B$9/100,IF(Eingaben!$B$5="Report",Q7*Eingaben!$B$31/100,SUMIFS(Intervalle!$K$102:$K$197,Intervalle!$G$102:$G$197,"ST")))*(1+Eingaben!$B$7)) -> 0.003977932 | AB7: =IF($B7<>"OK","",IF(A7<Eingaben!$B$18,R7*Eingaben!$B$9/100,IF(Eingaben!$B$5="Report",R7*Eingaben!$B$32/100,SUMIFS(Intervalle!$K$102:$K$197,Intervalle!$G$102:$G$197,"HT")))*(1+Eingaben!$B$7)) -> 0.033300008 | AC7: =IF($B7<>"OK","",-SUM(Y7:AB7)) -> -0.001573418 | AD7: =IF($B7<>"OK","",SUM(S7:AB7)) -> 0.33991141 | AE7: =IF($B7<>"OK","",IF(Eingaben!$B$5="Report",Reportdaten!L7,"")) -> 0.34 | AF7: =IF($B7<>"OK","",IF(Eingaben!$B$5="Report",AD7-AE7,"")) -> -8.8585836e-05
A8: 46145 | B8: =IF(Eingaben!$B$27<>"OK","NETZREFERENZ FEHLT",IF(AND(A8<Eingaben!$B$18,NOT(ISNUMBER(Eingaben!$B$9))),"NORMALER NETZPREIS FEHLT",IF(Eingaben!$B$5="Report",IF(Reportdaten!Q8<>"complete","REPORT UNVOLLSTAENDIG",IF(AND(SUM(Reportdaten!I8:K8)>0,NOT(ISNUMBER(Eingaben!$B$13))),"HEAT-PREIS FEHLT","OK")),IF(COUNTIF(Intervalle!J198:J293,"OK")=96,"OK","INTERVALLE UNVOLLSTAENDIG")))) -> OK | C8: =IF($B8<>"OK","",IF(Eingaben!$B$5="Report",Reportdaten!C8,SUMIFS(Intervalle!$C$198:$C$293,Intervalle!$F$198:$F$293,"GO",Intervalle!$G$198:$G$293,"NT"))) -> 0.066 | D8: =IF($B8<>"OK","",IF(Eingaben!$B$5="Report",Reportdaten!D8,SUMIFS(Intervalle!$C$198:$C$293,Intervalle!$F$198:$F$293,"GO",Intervalle!$G$198:$G$293,"ST"))) -> 0 | E8: =IF($B8<>"OK","",IF(Eingaben!$B$5="Report",Reportdaten!E8,SUMIFS(Intervalle!$C$198:$C$293,Intervalle!$F$198:$F$293,"GO",Intervalle!$G$198:$G$293,"HT"))) -> 0 | F8: =IF($B8<>"OK","",IF(Eingaben!$B$5="Report",Reportdaten!F8,SUMIFS(Intervalle!$C$198:$C$293,Intervalle!$F$198:$F$293,"STANDARD",Intervalle!$G$198:$G$293,"NT"))) -> 0.024 | G8: =IF($B8<>"OK","",IF(Eingaben!$B$5="Report",Reportdaten!G8,SUMIFS(Intervalle!$C$198:$C$293,Intervalle!$F$198:$F$293,"STANDARD",Intervalle!$G$198:$G$293,"ST"))) -> 0.07 | H8: =IF($B8<>"OK","",IF(Eingaben!$B$5="Report",Reportdaten!H8,SUMIFS(Intervalle!$C$198:$C$293,Intervalle!$F$198:$F$293,"STANDARD",Intervalle!$G$198:$G$293,"HT"))) -> 0.051 | I8: =IF($B8<>"OK","",IF(Eingaben!$B$5="Report",Reportdaten!I8,SUMIFS(Intervalle!$C$198:$C$293,Intervalle!$F$198:$F$293,"HEAT",Intervalle!$G$198:$G$293,"NT"))) -> 0 | J8: =IF($B8<>"OK","",IF(Eingaben!$B$5="Report",Reportdaten!J8,SUMIFS(Intervalle!$C$198:$C$293,Intervalle!$F$198:$F$293,"HEAT",Intervalle!$G$198:$G$293,"ST"))) -> 0 | K8: =IF($B8<>"OK","",IF(Eingaben!$B$5="Report",Reportdaten!K8,SUMIFS(Intervalle!$C$198:$C$293,Intervalle!$F$198:$F$293,"HEAT",Intervalle!$G$198:$G$293,"HT"))) -> 0 | L8: =IF($B8<>"OK","",SUM(C8:K8)) -> 0.211 | M8: =IF($B8<>"OK","",SUM(C8:E8)) -> 0.066 | N8: =IF($B8<>"OK","",SUM(F8:H8)) -> 0.145 | O8: =IF($B8<>"OK","",SUM(I8:K8)) -> 0 | P8: =IF($B8<>"OK","",C8+F8+I8) -> 0.09 | Q8: =IF($B8<>"OK","",D8+G8+J8) -> 0.07 | R8: =IF($B8<>"OK","",E8+H8+K8) -> 0.051 | S8: =IF($B8<>"OK","",M8*Eingaben!$B$11/100) -> 0.009943164 | T8: =IF($B8<>"OK","",N8*Eingaben!$B$12/100) -> 0.04099788 | U8: =IF($B8<>"OK","",IF(O8=0,0,O8*Eingaben!$B$13/100)) -> 0 | V8: =IF($B8<>"OK","",IF(Eingaben!$B$15="Zeitanteilig",Eingaben!$B$14*12/365,Eingaben!$B$14/Eingaben!$B$25)) -> 0.58352384 | W8: =IF($B8<>"OK","",L8*(IF(A8<Eingaben!$B$18,Eingaben!$B$9,Eingaben!$B$10)-Eingaben!$B$8)*(1+Eingaben!$B$7)/100) -> 0 | X8: =IF($B8<>"OK","",IF(A8>=Eingaben!$B$17,-Eingaben!$B$16*(1+Eingaben!$B$7)/Eingaben!$B$26,0)) -> -0.35318548 | Y8: =IF($B8<>"OK","",-L8*IF(A8<Eingaben!$B$18,Eingaben!$B$9,Eingaben!$B$10)*(1+Eingaben!$B$7)/100) -> -0.019208385 | Z8: =IF($B8<>"OK","",IF(A8<Eingaben!$B$18,P8*Eingaben!$B$9/100,IF(Eingaben!$B$5="Report",P8*Eingaben!$B$30/100,SUMIFS(Intervalle!$K$198:$K$293,Intervalle!$G$198:$G$293,"NT")))*(1+Eingaben!$B$7)) -> 0.00175644 | AA8: =IF($B8<>"OK","",IF(A8<Eingaben!$B$18,Q8*Eingaben!$B$9/100,IF(Eingaben!$B$5="Report",Q8*Eingaben!$B$31/100,SUMIFS(Intervalle!$K$198:$K$293,Intervalle!$G$198:$G$293,"ST")))*(1+Eingaben!$B$7)) -> 0.00456484 | AB8: =IF($B8<>"OK","",IF(A8<Eingaben!$B$18,R8*Eingaben!$B$9/100,IF(Eingaben!$B$5="Report",R8*Eingaben!$B$32/100,SUMIFS(Intervalle!$K$198:$K$293,Intervalle!$G$198:$G$293,"HT")))*(1+Eingaben!$B$7)) -> 0.006384588 | AC8: =IF($B8<>"OK","",-SUM(Y8:AB8)) -> 0.006502517 | AD8: =IF($B8<>"OK","",SUM(S8:AB8)) -> 0.27477688 | AE8: =IF($B8<>"OK","",IF(Eingaben!$B$5="Report",Reportdaten!L8,"")) -> 0.27 | AF8: =IF($B8<>"OK","",IF(Eingaben!$B$5="Report",AD8-AE8,"")) -> 0.0047768832
A9: 46146 | B9: =IF(Eingaben!$B$27<>"OK","NETZREFERENZ FEHLT",IF(AND(A9<Eingaben!$B$18,NOT(ISNUMBER(Eingaben!$B$9))),"NORMALER NETZPREIS FEHLT",IF(Eingaben!$B$5="Report",IF(Reportdaten!Q9<>"complete","REPORT UNVOLLSTAENDIG",IF(AND(SUM(Reportdaten!I9:K9)>0,NOT(ISNUMBER(Eingaben!$B$13))),"HEAT-PREIS FEHLT","OK")),IF(COUNTIF(Intervalle!J294:J389,"OK")=96,"OK","INTERVALLE UNVOLLSTAENDIG")))) -> OK | C9: =IF($B9<>"OK","",IF(Eingaben!$B$5="Report",Reportdaten!C9,SUMIFS(Intervalle!$C$294:$C$389,Intervalle!$F$294:$F$389,"GO",Intervalle!$G$294:$G$389,"NT"))) -> 0.059 | D9: =IF($B9<>"OK","",IF(Eingaben!$B$5="Report",Reportdaten!D9,SUMIFS(Intervalle!$C$294:$C$389,Intervalle!$F$294:$F$389,"GO",Intervalle!$G$294:$G$389,"ST"))) -> 0 | E9: =IF($B9<>"OK","",IF(Eingaben!$B$5="Report",Reportdaten!E9,SUMIFS(Intervalle!$C$294:$C$389,Intervalle!$F$294:$F$389,"GO",Intervalle!$G$294:$G$389,"HT"))) -> 0 | F9: =IF($B9<>"OK","",IF(Eingaben!$B$5="Report",Reportdaten!F9,SUMIFS(Intervalle!$C$294:$C$389,Intervalle!$F$294:$F$389,"STANDARD",Intervalle!$G$294:$G$389,"NT"))) -> 0.018 | G9: =IF($B9<>"OK","",IF(Eingaben!$B$5="Report",Reportdaten!G9,SUMIFS(Intervalle!$C$294:$C$389,Intervalle!$F$294:$F$389,"STANDARD",Intervalle!$G$294:$G$389,"ST"))) -> 0.074 | H9: =IF($B9<>"OK","",IF(Eingaben!$B$5="Report",Reportdaten!H9,SUMIFS(Intervalle!$C$294:$C$389,Intervalle!$F$294:$F$389,"STANDARD",Intervalle!$G$294:$G$389,"HT"))) -> 0.042 | I9: =IF($B9<>"OK","",IF(Eingaben!$B$5="Report",Reportdaten!I9,SUMIFS(Intervalle!$C$294:$C$389,Intervalle!$F$294:$F$389,"HEAT",Intervalle!$G$294:$G$389,"NT"))) -> 0 | J9: =IF($B9<>"OK","",IF(Eingaben!$B$5="Report",Reportdaten!J9,SUMIFS(Intervalle!$C$294:$C$389,Intervalle!$F$294:$F$389,"HEAT",Intervalle!$G$294:$G$389,"ST"))) -> 0 | K9: =IF($B9<>"OK","",IF(Eingaben!$B$5="Report",Reportdaten!K9,SUMIFS(Intervalle!$C$294:$C$389,Intervalle!$F$294:$F$389,"HEAT",Intervalle!$G$294:$G$389,"HT"))) -> 0 | L9: =IF($B9<>"OK","",SUM(C9:K9)) -> 0.193 | M9: =IF($B9<>"OK","",SUM(C9:E9)) -> 0.059 | N9: =IF($B9<>"OK","",SUM(F9:H9)) -> 0.134 | O9: =IF($B9<>"OK","",SUM(I9:K9)) -> 0 | P9: =IF($B9<>"OK","",C9+F9+I9) -> 0.077 | Q9: =IF($B9<>"OK","",D9+G9+J9) -> 0.074 | R9: =IF($B9<>"OK","",E9+H9+K9) -> 0.042 | S9: =IF($B9<>"OK","",M9*Eingaben!$B$11/100) -> 0.008888586 | T9: =IF($B9<>"OK","",N9*Eingaben!$B$12/100) -> 0.037887696 | U9: =IF($B9<>"OK","",IF(O9=0,0,O9*Eingaben!$B$13/100)) -> 0 | V9: =IF($B9<>"OK","",IF(Eingaben!$B$15="Zeitanteilig",Eingaben!$B$14*12/365,Eingaben!$B$14/Eingaben!$B$25)) -> 0.58352384 | W9: =IF($B9<>"OK","",L9*(IF(A9<Eingaben!$B$18,Eingaben!$B$9,Eingaben!$B$10)-Eingaben!$B$8)*(1+Eingaben!$B$7)/100) -> 0 | X9: =IF($B9<>"OK","",IF(A9>=Eingaben!$B$17,-Eingaben!$B$16*(1+Eingaben!$B$7)/Eingaben!$B$26,0)) -> -0.35318548 | Y9: =IF($B9<>"OK","",-L9*IF(A9<Eingaben!$B$18,Eingaben!$B$9,Eingaben!$B$10)*(1+Eingaben!$B$7)/100) -> -0.017569755 | Z9: =IF($B9<>"OK","",IF(A9<Eingaben!$B$18,P9*Eingaben!$B$9/100,IF(Eingaben!$B$5="Report",P9*Eingaben!$B$30/100,SUMIFS(Intervalle!$K$294:$K$389,Intervalle!$G$294:$G$389,"NT")))*(1+Eingaben!$B$7)) -> 0.001502732 | AA9: =IF($B9<>"OK","",IF(A9<Eingaben!$B$18,Q9*Eingaben!$B$9/100,IF(Eingaben!$B$5="Report",Q9*Eingaben!$B$31/100,SUMIFS(Intervalle!$K$294:$K$389,Intervalle!$G$294:$G$389,"ST")))*(1+Eingaben!$B$7)) -> 0.004825688 | AB9: =IF($B9<>"OK","",IF(A9<Eingaben!$B$18,R9*Eingaben!$B$9/100,IF(Eingaben!$B$5="Report",R9*Eingaben!$B$32/100,SUMIFS(Intervalle!$K$294:$K$389,Intervalle!$G$294:$G$389,"HT")))*(1+Eingaben!$B$7)) -> 0.005257896 | AC9: =IF($B9<>"OK","",-SUM(Y9:AB9)) -> 0.005983439 | AD9: =IF($B9<>"OK","",SUM(S9:AB9)) -> 0.2711312 | AE9: =IF($B9<>"OK","",IF(Eingaben!$B$5="Report",Reportdaten!L9,"")) -> 0.27 | AF9: =IF($B9<>"OK","",IF(Eingaben!$B$5="Report",AD9-AE9,"")) -> 0.0011311992
A10: 46147 | B10: =IF(Eingaben!$B$27<>"OK","NETZREFERENZ FEHLT",IF(AND(A10<Eingaben!$B$18,NOT(ISNUMBER(Eingaben!$B$9))),"NORMALER NETZPREIS FEHLT",IF(Eingaben!$B$5="Report",IF(Reportdaten!Q10<>"complete","REPORT UNVOLLSTAENDIG",IF(AND(SUM(Reportdaten!I10:K10)>0,NOT(ISNUMBER(Eingaben!$B$13))),"HEAT-PREIS FEHLT","OK")),IF(COUNTIF(Intervalle!J390:J485,"OK")=96,"OK","INTERVALLE UNVOLLSTAENDIG")))) -> OK | C10: =IF($B10<>"OK","",IF(Eingaben!$B$5="Report",Reportdaten!C10,SUMIFS(Intervalle!$C$390:$C$485,Intervalle!$F$390:$F$485,"GO",Intervalle!$G$390:$G$485,"NT"))) -> 0.521 | D10: =IF($B10<>"OK","",IF(Eingaben!$B$5="Report",Reportdaten!D10,SUMIFS(Intervalle!$C$390:$C$485,Intervalle!$F$390:$F$485,"GO",Intervalle!$G$390:$G$485,"ST"))) -> 0 | E10: =IF($B10<>"OK","",IF(Eingaben!$B$5="Report",Reportdaten!E10,SUMIFS(Intervalle!$C$390:$C$485,Intervalle!$F$390:$F$485,"GO",Intervalle!$G$390:$G$485,"HT"))) -> 0 | F10: =IF($B10<>"OK","",IF(Eingaben!$B$5="Report",Reportdaten!F10,SUMIFS(Intervalle!$C$390:$C$485,Intervalle!$F$390:$F$485,"STANDARD",Intervalle!$G$390:$G$485,"NT"))) -> 0.003 | G10: =IF($B10<>"OK","",IF(Eingaben!$B$5="Report",Reportdaten!G10,SUMIFS(Intervalle!$C$390:$C$485,Intervalle!$F$390:$F$485,"STANDARD",Intervalle!$G$390:$G$485,"ST"))) -> 0.035 | H10: =IF($B10<>"OK","",IF(Eingaben!$B$5="Report",Reportdaten!H10,SUMIFS(Intervalle!$C$390:$C$485,Intervalle!$F$390:$F$485,"STANDARD",Intervalle!$G$390:$G$485,"HT"))) -> 0.005 | I10: =IF($B10<>"OK","",IF(Eingaben!$B$5="Report",Reportdaten!I10,SUMIFS(Intervalle!$C$390:$C$485,Intervalle!$F$390:$F$485,"HEAT",Intervalle!$G$390:$G$485,"NT"))) -> 0 | J10: =IF($B10<>"OK","",IF(Eingaben!$B$5="Report",Reportdaten!J10,SUMIFS(Intervalle!$C$390:$C$485,Intervalle!$F$390:$F$485,"HEAT",Intervalle!$G$390:$G$485,"ST"))) -> 0 | K10: =IF($B10<>"OK","",IF(Eingaben!$B$5="Report",Reportdaten!K10,SUMIFS(Intervalle!$C$390:$C$485,Intervalle!$F$390:$F$485,"HEAT",Intervalle!$G$390:$G$485,"HT"))) -> 0 | L10: =IF($B10<>"OK","",SUM(C10:K10)) -> 0.564 | M10: =IF($B10<>"OK","",SUM(C10:E10)) -> 0.521 | N10: =IF($B10<>"OK","",SUM(F10:H10)) -> 0.043 | O10: =IF($B10<>"OK","",SUM(I10:K10)) -> 0 | P10: =IF($B10<>"OK","",C10+F10+I10) -> 0.524 | Q10: =IF($B10<>"OK","",D10+G10+J10) -> 0.035 | R10: =IF($B10<>"OK","",E10+H10+K10) -> 0.005 | S10: =IF($B10<>"OK","",M10*Eingaben!$B$11/100) -> 0.078490734 | T10: =IF($B10<>"OK","",N10*Eingaben!$B$12/100) -> 0.012157992 | U10: =IF($B10<>"OK","",IF(O10=0,0,O10*Eingaben!$B$13/100)) -> 0 | V10: =IF($B10<>"OK","",IF(Eingaben!$B$15="Zeitanteilig",Eingaben!$B$14*12/365,Eingaben!$B$14/Eingaben!$B$25)) -> 0.58352384 | W10: =IF($B10<>"OK","",L10*(IF(A10<Eingaben!$B$18,Eingaben!$B$9,Eingaben!$B$10)-Eingaben!$B$8)*(1+Eingaben!$B$7)/100) -> 0 | X10: =IF($B10<>"OK","",IF(A10>=Eingaben!$B$17,-Eingaben!$B$16*(1+Eingaben!$B$7)/Eingaben!$B$26,0)) -> -0.35318548 | Y10: =IF($B10<>"OK","",-L10*IF(A10<Eingaben!$B$18,Eingaben!$B$9,Eingaben!$B$10)*(1+Eingaben!$B$7)/100) -> -0.05134374 | Z10: =IF($B10<>"OK","",IF(A10<Eingaben!$B$18,P10*Eingaben!$B$9/100,IF(Eingaben!$B$5="Report",P10*Eingaben!$B$30/100,SUMIFS(Intervalle!$K$390:$K$485,Intervalle!$G$390:$G$485,"NT")))*(1+Eingaben!$B$7)) -> 0.010226384 | AA10: =IF($B10<>"OK","",IF(A10<Eingaben!$B$18,Q10*Eingaben!$B$9/100,IF(Eingaben!$B$5="Report",Q10*Eingaben!$B$31/100,SUMIFS(Intervalle!$K$390:$K$485,Intervalle!$G$390:$G$485,"ST")))*(1+Eingaben!$B$7)) -> 0.00228242 | AB10: =IF($B10<>"OK","",IF(A10<Eingaben!$B$18,R10*Eingaben!$B$9/100,IF(Eingaben!$B$5="Report",R10*Eingaben!$B$32/100,SUMIFS(Intervalle!$K$390:$K$485,Intervalle!$G$390:$G$485,"HT")))*(1+Eingaben!$B$7)) -> 0.00062594 | AC10: =IF($B10<>"OK","",-SUM(Y10:AB10)) -> 0.038208996 | AD10: =IF($B10<>"OK","",SUM(S10:AB10)) -> 0.28277809 | AE10: =IF($B10<>"OK","",IF(Eingaben!$B$5="Report",Reportdaten!L10,"")) -> 0.28 | AF10: =IF($B10<>"OK","",IF(Eingaben!$B$5="Report",AD10-AE10,"")) -> 0.0027780862
A11: 46148 | B11: =IF(Eingaben!$B$27<>"OK","NETZREFERENZ FEHLT",IF(AND(A11<Eingaben!$B$18,NOT(ISNUMBER(Eingaben!$B$9))),"NORMALER NETZPREIS FEHLT",IF(Eingaben!$B$5="Report",IF(Reportdaten!Q11<>"complete","REPORT UNVOLLSTAENDIG",IF(AND(SUM(Reportdaten!I11:K11)>0,NOT(ISNUMBER(Eingaben!$B$13))),"HEAT-PREIS FEHLT","OK")),IF(COUNTIF(Intervalle!J486:J581,"OK")=96,"OK","INTERVALLE UNVOLLSTAENDIG")))) -> OK | C11: =IF($B11<>"OK","",IF(Eingaben!$B$5="Report",Reportdaten!C11,SUMIFS(Intervalle!$C$486:$C$581,Intervalle!$F$486:$F$581,"GO",Intervalle!$G$486:$G$581,"NT"))) -> 0.15 | D11: =IF($B11<>"OK","",IF(Eingaben!$B$5="Report",Reportdaten!D11,SUMIFS(Intervalle!$C$486:$C$581,Intervalle!$F$486:$F$581,"GO",Intervalle!$G$486:$G$581,"ST"))) -> 0 | E11: =IF($B11<>"OK","",IF(Eingaben!$B$5="Report",Reportdaten!E11,SUMIFS(Intervalle!$C$486:$C$581,Intervalle!$F$486:$F$581,"GO",Intervalle!$G$486:$G$581,"HT"))) -> 0 | F11: =IF($B11<>"OK","",IF(Eingaben!$B$5="Report",Reportdaten!F11,SUMIFS(Intervalle!$C$486:$C$581,Intervalle!$F$486:$F$581,"STANDARD",Intervalle!$G$486:$G$581,"NT"))) -> 0.067 | G11: =IF($B11<>"OK","",IF(Eingaben!$B$5="Report",Reportdaten!G11,SUMIFS(Intervalle!$C$486:$C$581,Intervalle!$F$486:$F$581,"STANDARD",Intervalle!$G$486:$G$581,"ST"))) -> 0.188 | H11: =IF($B11<>"OK","",IF(Eingaben!$B$5="Report",Reportdaten!H11,SUMIFS(Intervalle!$C$486:$C$581,Intervalle!$F$486:$F$581,"STANDARD",Intervalle!$G$486:$G$581,"HT"))) -> 0.041 | I11: =IF($B11<>"OK","",IF(Eingaben!$B$5="Report",Reportdaten!I11,SUMIFS(Intervalle!$C$486:$C$581,Intervalle!$F$486:$F$581,"HEAT",Intervalle!$G$486:$G$581,"NT"))) -> 0 | J11: =IF($B11<>"OK","",IF(Eingaben!$B$5="Report",Reportdaten!J11,SUMIFS(Intervalle!$C$486:$C$581,Intervalle!$F$486:$F$581,"HEAT",Intervalle!$G$486:$G$581,"ST"))) -> 0 | K11: =IF($B11<>"OK","",IF(Eingaben!$B$5="Report",Reportdaten!K11,SUMIFS(Intervalle!$C$486:$C$581,Intervalle!$F$486:$F$581,"HEAT",Intervalle!$G$486:$G$581,"HT"))) -> 0 | L11: =IF($B11<>"OK","",SUM(C11:K11)) -> 0.446 | M11: =IF($B11<>"OK","",SUM(C11:E11)) -> 0.15 | N11: =IF($B11<>"OK","",SUM(F11:H11)) -> 0.296 | O11: =IF($B11<>"OK","",SUM(I11:K11)) -> 0 | P11: =IF($B11<>"OK","",C11+F11+I11) -> 0.217 | Q11: =IF($B11<>"OK","",D11+G11+J11) -> 0.188 | R11: =IF($B11<>"OK","",E11+H11+K11) -> 0.041 | S11: =IF($B11<>"OK","",M11*Eingaben!$B$11/100) -> 0.0225981 | T11: =IF($B11<>"OK","",N11*Eingaben!$B$12/100) -> 0.083692224 | U11: =IF($B11<>"OK","",IF(O11=0,0,O11*Eingaben!$B$13/100)) -> 0 | V11: =IF($B11<>"OK","",IF(Eingaben!$B$15="Zeitanteilig",Eingaben!$B$14*12/365,Eingaben!$B$14/Eingaben!$B$25)) -> 0.58352384 | W11: =IF($B11<>"OK","",L11*(IF(A11<Eingaben!$B$18,Eingaben!$B$9,Eingaben!$B$10)-Eingaben!$B$8)*(1+Eingaben!$B$7)/100) -> 0 | X11: =IF($B11<>"OK","",IF(A11>=Eingaben!$B$17,-Eingaben!$B$16*(1+Eingaben!$B$7)/Eingaben!$B$26,0)) -> -0.35318548 | Y11: =IF($B11<>"OK","",-L11*IF(A11<Eingaben!$B$18,Eingaben!$B$9,Eingaben!$B$10)*(1+Eingaben!$B$7)/100) -> -0.04060161 | Z11: =IF($B11<>"OK","",IF(A11<Eingaben!$B$18,P11*Eingaben!$B$9/100,IF(Eingaben!$B$5="Report",P11*Eingaben!$B$30/100,SUMIFS(Intervalle!$K$486:$K$581,Intervalle!$G$486:$G$581,"NT")))*(1+Eingaben!$B$7)) -> 0.004234972 | AA11: =IF($B11<>"OK","",IF(A11<Eingaben!$B$18,Q11*Eingaben!$B$9/100,IF(Eingaben!$B$5="Report",Q11*Eingaben!$B$31/100,SUMIFS(Intervalle!$K$486:$K$581,Intervalle!$G$486:$G$581,"ST")))*(1+Eingaben!$B$7)) -> 0.012259856 | AB11: =IF($B11<>"OK","",IF(A11<Eingaben!$B$18,R11*Eingaben!$B$9/100,IF(Eingaben!$B$5="Report",R11*Eingaben!$B$32/100,SUMIFS(Intervalle!$K$486:$K$581,Intervalle!$G$486:$G$581,"HT")))*(1+Eingaben!$B$7)) -> 0.005132708 | AC11: =IF($B11<>"OK","",-SUM(Y11:AB11)) -> 0.018974074 | AD11: =IF($B11<>"OK","",SUM(S11:AB11)) -> 0.31765461 | AE11: =IF($B11<>"OK","",IF(Eingaben!$B$5="Report",Reportdaten!L11,"")) -> 0.32 | AF11: =IF($B11<>"OK","",IF(Eingaben!$B$5="Report",AD11-AE11,"")) -> -0.0023453938
A12: 46149 | B12: =IF(Eingaben!$B$27<>"OK","NETZREFERENZ FEHLT",IF(AND(A12<Eingaben!$B$18,NOT(ISNUMBER(Eingaben!$B$9))),"NORMALER NETZPREIS FEHLT",IF(Eingaben!$B$5="Report",IF(Reportdaten!Q12<>"complete","REPORT UNVOLLSTAENDIG",IF(AND(SUM(Reportdaten!I12:K12)>0,NOT(ISNUMBER(Eingaben!$B$13))),"HEAT-PREIS FEHLT","OK")),IF(COUNTIF(Intervalle!J582:J677,"OK")=96,"OK","INTERVALLE UNVOLLSTAENDIG")))) -> OK | C12: =IF($B12<>"OK","",IF(Eingaben!$B$5="Report",Reportdaten!C12,SUMIFS(Intervalle!$C$582:$C$677,Intervalle!$F$582:$F$677,"GO",Intervalle!$G$582:$G$677,"NT"))) -> 0.066 | D12: =IF($B12<>"OK","",IF(Eingaben!$B$5="Report",Reportdaten!D12,SUMIFS(Intervalle!$C$582:$C$677,Intervalle!$F$582:$F$677,"GO",Intervalle!$G$582:$G$677,"ST"))) -> 0 | E12: =IF($B12<>"OK","",IF(Eingaben!$B$5="Report",Reportdaten!E12,SUMIFS(Intervalle!$C$582:$C$677,Intervalle!$F$582:$F$677,"GO",Intervalle!$G$582:$G$677,"HT"))) -> 0 | F12: =IF($B12<>"OK","",IF(Eingaben!$B$5="Report",Reportdaten!F12,SUMIFS(Intervalle!$C$582:$C$677,Intervalle!$F$582:$F$677,"STANDARD",Intervalle!$G$582:$G$677,"NT"))) -> 0.044 | G12: =IF($B12<>"OK","",IF(Eingaben!$B$5="Report",Reportdaten!G12,SUMIFS(Intervalle!$C$582:$C$677,Intervalle!$F$582:$F$677,"STANDARD",Intervalle!$G$582:$G$677,"ST"))) -> 0.118 | H12: =IF($B12<>"OK","",IF(Eingaben!$B$5="Report",Reportdaten!H12,SUMIFS(Intervalle!$C$582:$C$677,Intervalle!$F$582:$F$677,"STANDARD",Intervalle!$G$582:$G$677,"HT"))) -> 0.134 | I12: =IF($B12<>"OK","",IF(Eingaben!$B$5="Report",Reportdaten!I12,SUMIFS(Intervalle!$C$582:$C$677,Intervalle!$F$582:$F$677,"HEAT",Intervalle!$G$582:$G$677,"NT"))) -> 0 | J12: =IF($B12<>"OK","",IF(Eingaben!$B$5="Report",Reportdaten!J12,SUMIFS(Intervalle!$C$582:$C$677,Intervalle!$F$582:$F$677,"HEAT",Intervalle!$G$582:$G$677,"ST"))) -> 0 | K12: =IF($B12<>"OK","",IF(Eingaben!$B$5="Report",Reportdaten!K12,SUMIFS(Intervalle!$C$582:$C$677,Intervalle!$F$582:$F$677,"HEAT",Intervalle!$G$582:$G$677,"HT"))) -> 0 | L12: =IF($B12<>"OK","",SUM(C12:K12)) -> 0.362 | M12: =IF($B12<>"OK","",SUM(C12:E12)) -> 0.066 | N12: =IF($B12<>"OK","",SUM(F12:H12)) -> 0.296 | O12: =IF($B12<>"OK","",SUM(I12:K12)) -> 0 | P12: =IF($B12<>"OK","",C12+F12+I12) -> 0.11 | Q12: =IF($B12<>"OK","",D12+G12+J12) -> 0.118 | R12: =IF($B12<>"OK","",E12+H12+K12) -> 0.134 | S12: =IF($B12<>"OK","",M12*Eingaben!$B$11/100) -> 0.009943164 | T12: =IF($B12<>"OK","",N12*Eingaben!$B$12/100) -> 0.083692224 | U12: =IF($B12<>"OK","",IF(O12=0,0,O12*Eingaben!$B$13/100)) -> 0 | V12: =IF($B12<>"OK","",IF(Eingaben!$B$15="Zeitanteilig",Eingaben!$B$14*12/365,Eingaben!$B$14/Eingaben!$B$25)) -> 0.58352384 | W12: =IF($B12<>"OK","",L12*(IF(A12<Eingaben!$B$18,Eingaben!$B$9,Eingaben!$B$10)-Eingaben!$B$8)*(1+Eingaben!$B$7)/100) -> 0 | X12: =IF($B12<>"OK","",IF(A12>=Eingaben!$B$17,-Eingaben!$B$16*(1+Eingaben!$B$7)/Eingaben!$B$26,0)) -> -0.35318548 | Y12: =IF($B12<>"OK","",-L12*IF(A12<Eingaben!$B$18,Eingaben!$B$9,Eingaben!$B$10)*(1+Eingaben!$B$7)/100) -> -0.03295467 | Z12: =IF($B12<>"OK","",IF(A12<Eingaben!$B$18,P12*Eingaben!$B$9/100,IF(Eingaben!$B$5="Report",P12*Eingaben!$B$30/100,SUMIFS(Intervalle!$K$582:$K$677,Intervalle!$G$582:$G$677,"NT")))*(1+Eingaben!$B$7)) -> 0.00214676 | AA12: =IF($B12<>"OK","",IF(A12<Eingaben!$B$18,Q12*Eingaben!$B$9/100,IF(Eingaben!$B$5="Report",Q12*Eingaben!$B$31/100,SUMIFS(Intervalle!$K$582:$K$677,Intervalle!$G$582:$G$677,"ST")))*(1+Eingaben!$B$7)) -> 0.007695016 | AB12: =IF($B12<>"OK","",IF(A12<Eingaben!$B$18,R12*Eingaben!$B$9/100,IF(Eingaben!$B$5="Report",R12*Eingaben!$B$32/100,SUMIFS(Intervalle!$K$582:$K$677,Intervalle!$G$582:$G$677,"HT")))*(1+Eingaben!$B$7)) -> 0.016775192 | AC12: =IF($B12<>"OK","",-SUM(Y12:AB12)) -> 0.006337702 | AD12: =IF($B12<>"OK","",SUM(S12:AB12)) -> 0.31763604 | AE12: =IF($B12<>"OK","",IF(Eingaben!$B$5="Report",Reportdaten!L12,"")) -> 0.32 | AF12: =IF($B12<>"OK","",IF(Eingaben!$B$5="Report",AD12-AE12,"")) -> -0.0023639578
A13: 46150 | B13: =IF(Eingaben!$B$27<>"OK","NETZREFERENZ FEHLT",IF(AND(A13<Eingaben!$B$18,NOT(ISNUMBER(Eingaben!$B$9))),"NORMALER NETZPREIS FEHLT",IF(Eingaben!$B$5="Report",IF(Reportdaten!Q13<>"complete","REPORT UNVOLLSTAENDIG",IF(AND(SUM(Reportdaten!I13:K13)>0,NOT(ISNUMBER(Eingaben!$B$13))),"HEAT-PREIS FEHLT","OK")),IF(COUNTIF(Intervalle!J678:J773,"OK")=96,"OK","INTERVALLE UNVOLLSTAENDIG")))) -> OK | C13: =IF($B13<>"OK","",IF(Eingaben!$B$5="Report",Reportdaten!C13,SUMIFS(Intervalle!$C$678:$C$773,Intervalle!$F$678:$F$773,"GO",Intervalle!$G$678:$G$773,"NT"))) -> 0.291 | D13: =IF($B13<>"OK","",IF(Eingaben!$B$5="Report",Reportdaten!D13,SUMIFS(Intervalle!$C$678:$C$773,Intervalle!$F$678:$F$773,"GO",Intervalle!$G$678:$G$773,"ST"))) -> 0 | E13: =IF($B13<>"OK","",IF(Eingaben!$B$5="Report",Reportdaten!E13,SUMIFS(Intervalle!$C$678:$C$773,Intervalle!$F$678:$F$773,"GO",Intervalle!$G$678:$G$773,"HT"))) -> 0 | F13: =IF($B13<>"OK","",IF(Eingaben!$B$5="Report",Reportdaten!F13,SUMIFS(Intervalle!$C$678:$C$773,Intervalle!$F$678:$F$773,"STANDARD",Intervalle!$G$678:$G$773,"NT"))) -> 0.052 | G13: =IF($B13<>"OK","",IF(Eingaben!$B$5="Report",Reportdaten!G13,SUMIFS(Intervalle!$C$678:$C$773,Intervalle!$F$678:$F$773,"STANDARD",Intervalle!$G$678:$G$773,"ST"))) -> 0.213 | H13: =IF($B13<>"OK","",IF(Eingaben!$B$5="Report",Reportdaten!H13,SUMIFS(Intervalle!$C$678:$C$773,Intervalle!$F$678:$F$773,"STANDARD",Intervalle!$G$678:$G$773,"HT"))) -> 0.023 | I13: =IF($B13<>"OK","",IF(Eingaben!$B$5="Report",Reportdaten!I13,SUMIFS(Intervalle!$C$678:$C$773,Intervalle!$F$678:$F$773,"HEAT",Intervalle!$G$678:$G$773,"NT"))) -> 0 | J13: =IF($B13<>"OK","",IF(Eingaben!$B$5="Report",Reportdaten!J13,SUMIFS(Intervalle!$C$678:$C$773,Intervalle!$F$678:$F$773,"HEAT",Intervalle!$G$678:$G$773,"ST"))) -> 0 | K13: =IF($B13<>"OK","",IF(Eingaben!$B$5="Report",Reportdaten!K13,SUMIFS(Intervalle!$C$678:$C$773,Intervalle!$F$678:$F$773,"HEAT",Intervalle!$G$678:$G$773,"HT"))) -> 0 | L13: =IF($B13<>"OK","",SUM(C13:K13)) -> 0.579 | M13: =IF($B13<>"OK","",SUM(C13:E13)) -> 0.291 | N13: =IF($B13<>"OK","",SUM(F13:H13)) -> 0.288 | O13: =IF($B13<>"OK","",SUM(I13:K13)) -> 0 | P13: =IF($B13<>"OK","",C13+F13+I13) -> 0.343 | Q13: =IF($B13<>"OK","",D13+G13+J13) -> 0.213 | R13: =IF($B13<>"OK","",E13+H13+K13) -> 0.023 | S13: =IF($B13<>"OK","",M13*Eingaben!$B$11/100) -> 0.043840314 | T13: =IF($B13<>"OK","",N13*Eingaben!$B$12/100) -> 0.081430272 | U13: =IF($B13<>"OK","",IF(O13=0,0,O13*Eingaben!$B$13/100)) -> 0 | V13: =IF($B13<>"OK","",IF(Eingaben!$B$15="Zeitanteilig",Eingaben!$B$14*12/365,Eingaben!$B$14/Eingaben!$B$25)) -> 0.58352384 | W13: =IF($B13<>"OK","",L13*(IF(A13<Eingaben!$B$18,Eingaben!$B$9,Eingaben!$B$10)-Eingaben!$B$8)*(1+Eingaben!$B$7)/100) -> 0 | X13: =IF($B13<>"OK","",IF(A13>=Eingaben!$B$17,-Eingaben!$B$16*(1+Eingaben!$B$7)/Eingaben!$B$26,0)) -> -0.35318548 | Y13: =IF($B13<>"OK","",-L13*IF(A13<Eingaben!$B$18,Eingaben!$B$9,Eingaben!$B$10)*(1+Eingaben!$B$7)/100) -> -0.052709265 | Z13: =IF($B13<>"OK","",IF(A13<Eingaben!$B$18,P13*Eingaben!$B$9/100,IF(Eingaben!$B$5="Report",P13*Eingaben!$B$30/100,SUMIFS(Intervalle!$K$678:$K$773,Intervalle!$G$678:$G$773,"NT")))*(1+Eingaben!$B$7)) -> 0.006693988 | AA13: =IF($B13<>"OK","",IF(A13<Eingaben!$B$18,Q13*Eingaben!$B$9/100,IF(Eingaben!$B$5="Report",Q13*Eingaben!$B$31/100,SUMIFS(Intervalle!$K$678:$K$773,Intervalle!$G$678:$G$773,"ST")))*(1+Eingaben!$B$7)) -> 0.013890156 | AB13: =IF($B13<>"OK","",IF(A13<Eingaben!$B$18,R13*Eingaben!$B$9/100,IF(Eingaben!$B$5="Report",R13*Eingaben!$B$32/100,SUMIFS(Intervalle!$K$678:$K$773,Intervalle!$G$678:$G$773,"HT")))*(1+Eingaben!$B$7)) -> 0.002879324 | AC13: =IF($B13<>"OK","",-SUM(Y13:AB13)) -> 0.029245797 | AD13: =IF($B13<>"OK","",SUM(S13:AB13)) -> 0.32636315 | AE13: =IF($B13<>"OK","",IF(Eingaben!$B$5="Report",Reportdaten!L13,"")) -> 0.33 | AF13: =IF($B13<>"OK","",IF(Eingaben!$B$5="Report",AD13-AE13,"")) -> -0.0036368548
A14: 46151 | B14: =IF(Eingaben!$B$27<>"OK","NETZREFERENZ FEHLT",IF(AND(A14<Eingaben!$B$18,NOT(ISNUMBER(Eingaben!$B$9))),"NORMALER NETZPREIS FEHLT",IF(Eingaben!$B$5="Report",IF(Reportdaten!Q14<>"complete","REPORT UNVOLLSTAENDIG",IF(AND(SUM(Reportdaten!I14:K14)>0,NOT(ISNUMBER(Eingaben!$B$13))),"HEAT-PREIS FEHLT","OK")),IF(COUNTIF(Intervalle!J774:J869,"OK")=96,"OK","INTERVALLE UNVOLLSTAENDIG")))) -> OK | C14: =IF($B14<>"OK","",IF(Eingaben!$B$5="Report",Reportdaten!C14,SUMIFS(Intervalle!$C$774:$C$869,Intervalle!$F$774:$F$869,"GO",Intervalle!$G$774:$G$869,"NT"))) -> 0.133 | D14: =IF($B14<>"OK","",IF(Eingaben!$B$5="Report",Reportdaten!D14,SUMIFS(Intervalle!$C$774:$C$869,Intervalle!$F$774:$F$869,"GO",Intervalle!$G$774:$G$869,"ST"))) -> 0 | E14: =IF($B14<>"OK","",IF(Eingaben!$B$5="Report",Reportdaten!E14,SUMIFS(Intervalle!$C$774:$C$869,Intervalle!$F$774:$F$869,"GO",Intervalle!$G$774:$G$869,"HT"))) -> 0 | F14: =IF($B14<>"OK","",IF(Eingaben!$B$5="Report",Reportdaten!F14,SUMIFS(Intervalle!$C$774:$C$869,Intervalle!$F$774:$F$869,"STANDARD",Intervalle!$G$774:$G$869,"NT"))) -> 0.069 | G14: =IF($B14<>"OK","",IF(Eingaben!$B$5="Report",Reportdaten!G14,SUMIFS(Intervalle!$C$774:$C$869,Intervalle!$F$774:$F$869,"STANDARD",Intervalle!$G$774:$G$869,"ST"))) -> 0.096 | H14: =IF($B14<>"OK","",IF(Eingaben!$B$5="Report",Reportdaten!H14,SUMIFS(Intervalle!$C$774:$C$869,Intervalle!$F$774:$F$869,"STANDARD",Intervalle!$G$774:$G$869,"HT"))) -> 0.018 | I14: =IF($B14<>"OK","",IF(Eingaben!$B$5="Report",Reportdaten!I14,SUMIFS(Intervalle!$C$774:$C$869,Intervalle!$F$774:$F$869,"HEAT",Intervalle!$G$774:$G$869,"NT"))) -> 0 | J14: =IF($B14<>"OK","",IF(Eingaben!$B$5="Report",Reportdaten!J14,SUMIFS(Intervalle!$C$774:$C$869,Intervalle!$F$774:$F$869,"HEAT",Intervalle!$G$774:$G$869,"ST"))) -> 0 | K14: =IF($B14<>"OK","",IF(Eingaben!$B$5="Report",Reportdaten!K14,SUMIFS(Intervalle!$C$774:$C$869,Intervalle!$F$774:$F$869,"HEAT",Intervalle!$G$774:$G$869,"HT"))) -> 0 | L14: =IF($B14<>"OK","",SUM(C14:K14)) -> 0.316 | M14: =IF($B14<>"OK","",SUM(C14:E14)) -> 0.133 | N14: =IF($B14<>"OK","",SUM(F14:H14)) -> 0.183 | O14: =IF($B14<>"OK","",SUM(I14:K14)) -> 0 | P14: =IF($B14<>"OK","",C14+F14+I14) -> 0.202 | Q14: =IF($B14<>"OK","",D14+G14+J14) -> 0.096 | R14: =IF($B14<>"OK","",E14+H14+K14) -> 0.018 | S14: =IF($B14<>"OK","",M14*Eingaben!$B$11/100) -> 0.020036982 | T14: =IF($B14<>"OK","",N14*Eingaben!$B$12/100) -> 0.051742152 | U14: =IF($B14<>"OK","",IF(O14=0,0,O14*Eingaben!$B$13/100)) -> 0 | V14: =IF($B14<>"OK","",IF(Eingaben!$B$15="Zeitanteilig",Eingaben!$B$14*12/365,Eingaben!$B$14/Eingaben!$B$25)) -> 0.58352384 | W14: =IF($B14<>"OK","",L14*(IF(A14<Eingaben!$B$18,Eingaben!$B$9,Eingaben!$B$10)-Eingaben!$B$8)*(1+Eingaben!$B$7)/100) -> 0 | X14: =IF($B14<>"OK","",IF(A14>=Eingaben!$B$17,-Eingaben!$B$16*(1+Eingaben!$B$7)/Eingaben!$B$26,0)) -> -0.35318548 | Y14: =IF($B14<>"OK","",-L14*IF(A14<Eingaben!$B$18,Eingaben!$B$9,Eingaben!$B$10)*(1+Eingaben!$B$7)/100) -> -0.02876706 | Z14: =IF($B14<>"OK","",IF(A14<Eingaben!$B$18,P14*Eingaben!$B$9/100,IF(Eingaben!$B$5="Report",P14*Eingaben!$B$30/100,SUMIFS(Intervalle!$K$774:$K$869,Intervalle!$G$774:$G$869,"NT")))*(1+Eingaben!$B$7)) -> 0.003942232 | AA14: =IF($B14<>"OK","",IF(A14<Eingaben!$B$18,Q14*Eingaben!$B$9/100,IF(Eingaben!$B$5="Report",Q14*Eingaben!$B$31/100,SUMIFS(Intervalle!$K$774:$K$869,Intervalle!$G$774:$G$869,"ST")))*(1+Eingaben!$B$7)) -> 0.006260352 | AB14: =IF($B14<>"OK","",IF(A14<Eingaben!$B$18,R14*Eingaben!$B$9/100,IF(Eingaben!$B$5="Report",R14*Eingaben!$B$32/100,SUMIFS(Intervalle!$K$774:$K$869,Intervalle!$G$774:$G$869,"HT")))*(1+Eingaben!$B$7)) -> 0.002253384 | AC14: =IF($B14<>"OK","",-SUM(Y14:AB14)) -> 0.016311092 | AD14: =IF($B14<>"OK","",SUM(S14:AB14)) -> 0.2858064 | AE14: =IF($B14<>"OK","",IF(Eingaben!$B$5="Report",Reportdaten!L14,"")) -> 0.29 | AF14: =IF($B14<>"OK","",IF(Eingaben!$B$5="Report",AD14-AE14,"")) -> -0.0041936018
A15: 46152 | B15: =IF(Eingaben!$B$27<>"OK","NETZREFERENZ FEHLT",IF(AND(A15<Eingaben!$B$18,NOT(ISNUMBER(Eingaben!$B$9))),"NORMALER NETZPREIS FEHLT",IF(Eingaben!$B$5="Report",IF(Reportdaten!Q15<>"complete","REPORT UNVOLLSTAENDIG",IF(AND(SUM(Reportdaten!I15:K15)>0,NOT(ISNUMBER(Eingaben!$B$13))),"HEAT-PREIS FEHLT","OK")),IF(COUNTIF(Intervalle!J870:J965,"OK")=96,"OK","INTERVALLE UNVOLLSTAENDIG")))) -> OK | C15: =IF($B15<>"OK","",IF(Eingaben!$B$5="Report",Reportdaten!C15,SUMIFS(Intervalle!$C$870:$C$965,Intervalle!$F$870:$F$965,"GO",Intervalle!$G$870:$G$965,"NT"))) -> 0.113 | D15: =IF($B15<>"OK","",IF(Eingaben!$B$5="Report",Reportdaten!D15,SUMIFS(Intervalle!$C$870:$C$965,Intervalle!$F$870:$F$965,"GO",Intervalle!$G$870:$G$965,"ST"))) -> 0 | E15: =IF($B15<>"OK","",IF(Eingaben!$B$5="Report",Reportdaten!E15,SUMIFS(Intervalle!$C$870:$C$965,Intervalle!$F$870:$F$965,"GO",Intervalle!$G$870:$G$965,"HT"))) -> 0 | F15: =IF($B15<>"OK","",IF(Eingaben!$B$5="Report",Reportdaten!F15,SUMIFS(Intervalle!$C$870:$C$965,Intervalle!$F$870:$F$965,"STANDARD",Intervalle!$G$870:$G$965,"NT"))) -> 0.039 | G15: =IF($B15<>"OK","",IF(Eingaben!$B$5="Report",Reportdaten!G15,SUMIFS(Intervalle!$C$870:$C$965,Intervalle!$F$870:$F$965,"STANDARD",Intervalle!$G$870:$G$965,"ST"))) -> 0.024 | H15: =IF($B15<>"OK","",IF(Eingaben!$B$5="Report",Reportdaten!H15,SUMIFS(Intervalle!$C$870:$C$965,Intervalle!$F$870:$F$965,"STANDARD",Intervalle!$G$870:$G$965,"HT"))) -> 0.024 | I15: =IF($B15<>"OK","",IF(Eingaben!$B$5="Report",Reportdaten!I15,SUMIFS(Intervalle!$C$870:$C$965,Intervalle!$F$870:$F$965,"HEAT",Intervalle!$G$870:$G$965,"NT"))) -> 0 | J15: =IF($B15<>"OK","",IF(Eingaben!$B$5="Report",Reportdaten!J15,SUMIFS(Intervalle!$C$870:$C$965,Intervalle!$F$870:$F$965,"HEAT",Intervalle!$G$870:$G$965,"ST"))) -> 0 | K15: =IF($B15<>"OK","",IF(Eingaben!$B$5="Report",Reportdaten!K15,SUMIFS(Intervalle!$C$870:$C$965,Intervalle!$F$870:$F$965,"HEAT",Intervalle!$G$870:$G$965,"HT"))) -> 0 | L15: =IF($B15<>"OK","",SUM(C15:K15)) -> 0.2 | M15: =IF($B15<>"OK","",SUM(C15:E15)) -> 0.113 | N15: =IF($B15<>"OK","",SUM(F15:H15)) -> 0.087 | O15: =IF($B15<>"OK","",SUM(I15:K15)) -> 0 | P15: =IF($B15<>"OK","",C15+F15+I15) -> 0.152 | Q15: =IF($B15<>"OK","",D15+G15+J15) -> 0.024 | R15: =IF($B15<>"OK","",E15+H15+K15) -> 0.024 | S15: =IF($B15<>"OK","",M15*Eingaben!$B$11/100) -> 0.017023902 | T15: =IF($B15<>"OK","",N15*Eingaben!$B$12/100) -> 0.024598728 | U15: =IF($B15<>"OK","",IF(O15=0,0,O15*Eingaben!$B$13/100)) -> 0 | V15: =IF($B15<>"OK","",IF(Eingaben!$B$15="Zeitanteilig",Eingaben!$B$14*12/365,Eingaben!$B$14/Eingaben!$B$25)) -> 0.58352384 | W15: =IF($B15<>"OK","",L15*(IF(A15<Eingaben!$B$18,Eingaben!$B$9,Eingaben!$B$10)-Eingaben!$B$8)*(1+Eingaben!$B$7)/100) -> 0 | X15: =IF($B15<>"OK","",IF(A15>=Eingaben!$B$17,-Eingaben!$B$16*(1+Eingaben!$B$7)/Eingaben!$B$26,0)) -> -0.35318548 | Y15: =IF($B15<>"OK","",-L15*IF(A15<Eingaben!$B$18,Eingaben!$B$9,Eingaben!$B$10)*(1+Eingaben!$B$7)/100) -> -0.018207 | Z15: =IF($B15<>"OK","",IF(A15<Eingaben!$B$18,P15*Eingaben!$B$9/100,IF(Eingaben!$B$5="Report",P15*Eingaben!$B$30/100,SUMIFS(Intervalle!$K$870:$K$965,Intervalle!$G$870:$G$965,"NT")))*(1+Eingaben!$B$7)) -> 0.002966432 | AA15: =IF($B15<>"OK","",IF(A15<Eingaben!$B$18,Q15*Eingaben!$B$9/100,IF(Eingaben!$B$5="Report",Q15*Eingaben!$B$31/100,SUMIFS(Intervalle!$K$870:$K$965,Intervalle!$G$870:$G$965,"ST")))*(1+Eingaben!$B$7)) -> 0.001565088 | AB15: =IF($B15<>"OK","",IF(A15<Eingaben!$B$18,R15*Eingaben!$B$9/100,IF(Eingaben!$B$5="Report",R15*Eingaben!$B$32/100,SUMIFS(Intervalle!$K$870:$K$965,Intervalle!$G$870:$G$965,"HT")))*(1+Eingaben!$B$7)) -> 0.003004512 | AC15: =IF($B15<>"OK","",-SUM(Y15:AB15)) -> 0.010670968 | AD15: =IF($B15<>"OK","",SUM(S15:AB15)) -> 0.26129002 | AE15: =IF($B15<>"OK","",IF(Eingaben!$B$5="Report",Reportdaten!L15,"")) -> 0.26 | AF15: =IF($B15<>"OK","",IF(Eingaben!$B$5="Report",AD15-AE15,"")) -> 0.0012900182
A16: 46153 | B16: =IF(Eingaben!$B$27<>"OK","NETZREFERENZ FEHLT",IF(AND(A16<Eingaben!$B$18,NOT(ISNUMBER(Eingaben!$B$9))),"NORMALER NETZPREIS FEHLT",IF(Eingaben!$B$5="Report",IF(Reportdaten!Q16<>"complete","REPORT UNVOLLSTAENDIG",IF(AND(SUM(Reportdaten!I16:K16)>0,NOT(ISNUMBER(Eingaben!$B$13))),"HEAT-PREIS FEHLT","OK")),IF(COUNTIF(Intervalle!J966:J1061,"OK")=96,"OK","INTERVALLE UNVOLLSTAENDIG")))) -> OK | C16: =IF($B16<>"OK","",IF(Eingaben!$B$5="Report",Reportdaten!C16,SUMIFS(Intervalle!$C$966:$C$1061,Intervalle!$F$966:$F$1061,"GO",Intervalle!$G$966:$G$1061,"NT"))) -> 0.064 | D16: =IF($B16<>"OK","",IF(Eingaben!$B$5="Report",Reportdaten!D16,SUMIFS(Intervalle!$C$966:$C$1061,Intervalle!$F$966:$F$1061,"GO",Intervalle!$G$966:$G$1061,"ST"))) -> 0 | E16: =IF($B16<>"OK","",IF(Eingaben!$B$5="Report",Reportdaten!E16,SUMIFS(Intervalle!$C$966:$C$1061,Intervalle!$F$966:$F$1061,"GO",Intervalle!$G$966:$G$1061,"HT"))) -> 0 | F16: =IF($B16<>"OK","",IF(Eingaben!$B$5="Report",Reportdaten!F16,SUMIFS(Intervalle!$C$966:$C$1061,Intervalle!$F$966:$F$1061,"STANDARD",Intervalle!$G$966:$G$1061,"NT"))) -> 0.081 | G16: =IF($B16<>"OK","",IF(Eingaben!$B$5="Report",Reportdaten!G16,SUMIFS(Intervalle!$C$966:$C$1061,Intervalle!$F$966:$F$1061,"STANDARD",Intervalle!$G$966:$G$1061,"ST"))) -> 0.179 | H16: =IF($B16<>"OK","",IF(Eingaben!$B$5="Report",Reportdaten!H16,SUMIFS(Intervalle!$C$966:$C$1061,Intervalle!$F$966:$F$1061,"STANDARD",Intervalle!$G$966:$G$1061,"HT"))) -> 0.096 | I16: =IF($B16<>"OK","",IF(Eingaben!$B$5="Report",Reportdaten!I16,SUMIFS(Intervalle!$C$966:$C$1061,Intervalle!$F$966:$F$1061,"HEAT",Intervalle!$G$966:$G$1061,"NT"))) -> 0 | J16: =IF($B16<>"OK","",IF(Eingaben!$B$5="Report",Reportdaten!J16,SUMIFS(Intervalle!$C$966:$C$1061,Intervalle!$F$966:$F$1061,"HEAT",Intervalle!$G$966:$G$1061,"ST"))) -> 0 | K16: =IF($B16<>"OK","",IF(Eingaben!$B$5="Report",Reportdaten!K16,SUMIFS(Intervalle!$C$966:$C$1061,Intervalle!$F$966:$F$1061,"HEAT",Intervalle!$G$966:$G$1061,"HT"))) -> 0 | L16: =IF($B16<>"OK","",SUM(C16:K16)) -> 0.42 | M16: =IF($B16<>"OK","",SUM(C16:E16)) -> 0.064 | N16: =IF($B16<>"OK","",SUM(F16:H16)) -> 0.356 | O16: =IF($B16<>"OK","",SUM(I16:K16)) -> 0 | P16: =IF($B16<>"OK","",C16+F16+I16) -> 0.145 | Q16: =IF($B16<>"OK","",D16+G16+J16) -> 0.179 | R16: =IF($B16<>"OK","",E16+H16+K16) -> 0.096 | S16: =IF($B16<>"OK","",M16*Eingaben!$B$11/100) -> 0.009641856 | T16: =IF($B16<>"OK","",N16*Eingaben!$B$12/100) -> 0.10065686 | U16: =IF($B16<>"OK","",IF(O16=0,0,O16*Eingaben!$B$13/100)) -> 0 | V16: =IF($B16<>"OK","",IF(Eingaben!$B$15="Zeitanteilig",Eingaben!$B$14*12/365,Eingaben!$B$14/Eingaben!$B$25)) -> 0.58352384 | W16: =IF($B16<>"OK","",L16*(IF(A16<Eingaben!$B$18,Eingaben!$B$9,Eingaben!$B$10)-Eingaben!$B$8)*(1+Eingaben!$B$7)/100) -> 0 | X16: =IF($B16<>"OK","",IF(A16>=Eingaben!$B$17,-Eingaben!$B$16*(1+Eingaben!$B$7)/Eingaben!$B$26,0)) -> -0.35318548 | Y16: =IF($B16<>"OK","",-L16*IF(A16<Eingaben!$B$18,Eingaben!$B$9,Eingaben!$B$10)*(1+Eingaben!$B$7)/100) -> -0.0382347 | Z16: =IF($B16<>"OK","",IF(A16<Eingaben!$B$18,P16*Eingaben!$B$9/100,IF(Eingaben!$B$5="Report",P16*Eingaben!$B$30/100,SUMIFS(Intervalle!$K$966:$K$1061,Intervalle!$G$966:$G$1061,"NT")))*(1+Eingaben!$B$7)) -> 0.00282982 | AA16: =IF($B16<>"OK","",IF(A16<Eingaben!$B$18,Q16*Eingaben!$B$9/100,IF(Eingaben!$B$5="Report",Q16*Eingaben!$B$31/100,SUMIFS(Intervalle!$K$966:$K$1061,Intervalle!$G$966:$G$1061,"ST")))*(1+Eingaben!$B$7)) -> 0.011672948 | AB16: =IF($B16<>"OK","",IF(A16<Eingaben!$B$18,R16*Eingaben!$B$9/100,IF(Eingaben!$B$5="Report",R16*Eingaben!$B$32/100,SUMIFS(Intervalle!$K$966:$K$1061,Intervalle!$G$966:$G$1061,"HT")))*(1+Eingaben!$B$7)) -> 0.012018048 | AC16: =IF($B16<>"OK","",-SUM(Y16:AB16)) -> 0.011713884 | AD16: =IF($B16<>"OK","",SUM(S16:AB16)) -> 0.32892319 | AE16: =IF($B16<>"OK","",IF(Eingaben!$B$5="Report",Reportdaten!L16,"")) -> 0.33 | AF16: =IF($B16<>"OK","",IF(Eingaben!$B$5="Report",AD16-AE16,"")) -> -0.0010768078
A17: 46154 | B17: =IF(Eingaben!$B$27<>"OK","NETZREFERENZ FEHLT",IF(AND(A17<Eingaben!$B$18,NOT(ISNUMBER(Eingaben!$B$9))),"NORMALER NETZPREIS FEHLT",IF(Eingaben!$B$5="Report",IF(Reportdaten!Q17<>"complete","REPORT UNVOLLSTAENDIG",IF(AND(SUM(Reportdaten!I17:K17)>0,NOT(ISNUMBER(Eingaben!$B$13))),"HEAT-PREIS FEHLT","OK")),IF(COUNTIF(Intervalle!J1062:J1157,"OK")=96,"OK","INTERVALLE UNVOLLSTAENDIG")))) -> OK | C17: =IF($B17<>"OK","",IF(Eingaben!$B$5="Report",Reportdaten!C17,SUMIFS(Intervalle!$C$1062:$C$1157,Intervalle!$F$1062:$F$1157,"GO",Intervalle!$G$1062:$G$1157,"NT"))) -> 0.086 | D17: =IF($B17<>"OK","",IF(Eingaben!$B$5="Report",Reportdaten!D17,SUMIFS(Intervalle!$C$1062:$C$1157,Intervalle!$F$1062:$F$1157,"GO",Intervalle!$G$1062:$G$1157,"ST"))) -> 0 | E17: =IF($B17<>"OK","",IF(Eingaben!$B$5="Report",Reportdaten!E17,SUMIFS(Intervalle!$C$1062:$C$1157,Intervalle!$F$1062:$F$1157,"GO",Intervalle!$G$1062:$G$1157,"HT"))) -> 0 | F17: =IF($B17<>"OK","",IF(Eingaben!$B$5="Report",Reportdaten!F17,SUMIFS(Intervalle!$C$1062:$C$1157,Intervalle!$F$1062:$F$1157,"STANDARD",Intervalle!$G$1062:$G$1157,"NT"))) -> 0.026 | G17: =IF($B17<>"OK","",IF(Eingaben!$B$5="Report",Reportdaten!G17,SUMIFS(Intervalle!$C$1062:$C$1157,Intervalle!$F$1062:$F$1157,"STANDARD",Intervalle!$G$1062:$G$1157,"ST"))) -> 0.164 | H17: =IF($B17<>"OK","",IF(Eingaben!$B$5="Report",Reportdaten!H17,SUMIFS(Intervalle!$C$1062:$C$1157,Intervalle!$F$1062:$F$1157,"STANDARD",Intervalle!$G$1062:$G$1157,"HT"))) -> 0.056 | I17: =IF($B17<>"OK","",IF(Eingaben!$B$5="Report",Reportdaten!I17,SUMIFS(Intervalle!$C$1062:$C$1157,Intervalle!$F$1062:$F$1157,"HEAT",Intervalle!$G$1062:$G$1157,"NT"))) -> 0 | J17: =IF($B17<>"OK","",IF(Eingaben!$B$5="Report",Reportdaten!J17,SUMIFS(Intervalle!$C$1062:$C$1157,Intervalle!$F$1062:$F$1157,"HEAT",Intervalle!$G$1062:$G$1157,"ST"))) -> 0 | K17: =IF($B17<>"OK","",IF(Eingaben!$B$5="Report",Reportdaten!K17,SUMIFS(Intervalle!$C$1062:$C$1157,Intervalle!$F$1062:$F$1157,"HEAT",Intervalle!$G$1062:$G$1157,"HT"))) -> 0 | L17: =IF($B17<>"OK","",SUM(C17:K17)) -> 0.332 | M17: =IF($B17<>"OK","",SUM(C17:E17)) -> 0.086 | N17: =IF($B17<>"OK","",SUM(F17:H17)) -> 0.246 | O17: =IF($B17<>"OK","",SUM(I17:K17)) -> 0 | P17: =IF($B17<>"OK","",C17+F17+I17) -> 0.112 | Q17: =IF($B17<>"OK","",D17+G17+J17) -> 0.164 | R17: =IF($B17<>"OK","",E17+H17+K17) -> 0.056 | S17: =IF($B17<>"OK","",M17*Eingaben!$B$11/100) -> 0.012956244 | T17: =IF($B17<>"OK","",N17*Eingaben!$B$12/100) -> 0.069555024 | U17: =IF($B17<>"OK","",IF(O17=0,0,O17*Eingaben!$B$13/100)) -> 0 | V17: =IF($B17<>"OK","",IF(Eingaben!$B$15="Zeitanteilig",Eingaben!$B$14*12/365,Eingaben!$B$14/Eingaben!$B$25)) -> 0.58352384 | W17: =IF($B17<>"OK","",L17*(IF(A17<Eingaben!$B$18,Eingaben!$B$9,Eingaben!$B$10)-Eingaben!$B$8)*(1+Eingaben!$B$7)/100) -> 0 | X17: =IF($B17<>"OK","",IF(A17>=Eingaben!$B$17,-Eingaben!$B$16*(1+Eingaben!$B$7)/Eingaben!$B$26,0)) -> -0.35318548 | Y17: =IF($B17<>"OK","",-L17*IF(A17<Eingaben!$B$18,Eingaben!$B$9,Eingaben!$B$10)*(1+Eingaben!$B$7)/100) -> -0.03022362 | Z17: =IF($B17<>"OK","",IF(A17<Eingaben!$B$18,P17*Eingaben!$B$9/100,IF(Eingaben!$B$5="Report",P17*Eingaben!$B$30/100,SUMIFS(Intervalle!$K$1062:$K$1157,Intervalle!$G$1062:$G$1157,"NT")))*(1+Eingaben!$B$7)) -> 0.002185792 | AA17: =IF($B17<>"OK","",IF(A17<Eingaben!$B$18,Q17*Eingaben!$B$9/100,IF(Eingaben!$B$5="Report",Q17*Eingaben!$B$31/100,SUMIFS(Intervalle!$K$1062:$K$1157,Intervalle!$G$1062:$G$1157,"ST")))*(1+Eingaben!$B$7)) -> 0.010694768 | AB17: =IF($B17<>"OK","",IF(A17<Eingaben!$B$18,R17*Eingaben!$B$9/100,IF(Eingaben!$B$5="Report",R17*Eingaben!$B$32/100,SUMIFS(Intervalle!$K$1062:$K$1157,Intervalle!$G$1062:$G$1157,"HT")))*(1+Eingaben!$B$7)) -> 0.007010528 | AC17: =IF($B17<>"OK","",-SUM(Y17:AB17)) -> 0.010332532 | AD17: =IF($B17<>"OK","",SUM(S17:AB17)) -> 0.30251709 | AE17: =IF($B17<>"OK","",IF(Eingaben!$B$5="Report",Reportdaten!L17,"")) -> 0.3 | AF17: =IF($B17<>"OK","",IF(Eingaben!$B$5="Report",AD17-AE17,"")) -> 0.0025170922
A18: 46155 | B18: =IF(Eingaben!$B$27<>"OK","NETZREFERENZ FEHLT",IF(AND(A18<Eingaben!$B$18,NOT(ISNUMBER(Eingaben!$B$9))),"NORMALER NETZPREIS FEHLT",IF(Eingaben!$B$5="Report",IF(Reportdaten!Q18<>"complete","REPORT UNVOLLSTAENDIG",IF(AND(SUM(Reportdaten!I18:K18)>0,NOT(ISNUMBER(Eingaben!$B$13))),"HEAT-PREIS FEHLT","OK")),IF(COUNTIF(Intervalle!J1158:J1253,"OK")=96,"OK","INTERVALLE UNVOLLSTAENDIG")))) -> OK | C18: =IF($B18<>"OK","",IF(Eingaben!$B$5="Report",Reportdaten!C18,SUMIFS(Intervalle!$C$1158:$C$1253,Intervalle!$F$1158:$F$1253,"GO",Intervalle!$G$1158:$G$1253,"NT"))) -> 0.07 | D18: =IF($B18<>"OK","",IF(Eingaben!$B$5="Report",Reportdaten!D18,SUMIFS(Intervalle!$C$1158:$C$1253,Intervalle!$F$1158:$F$1253,"GO",Intervalle!$G$1158:$G$1253,"ST"))) -> 0 | E18: =IF($B18<>"OK","",IF(Eingaben!$B$5="Report",Reportdaten!E18,SUMIFS(Intervalle!$C$1158:$C$1253,Intervalle!$F$1158:$F$1253,"GO",Intervalle!$G$1158:$G$1253,"HT"))) -> 0 | F18: =IF($B18<>"OK","",IF(Eingaben!$B$5="Report",Reportdaten!F18,SUMIFS(Intervalle!$C$1158:$C$1253,Intervalle!$F$1158:$F$1253,"STANDARD",Intervalle!$G$1158:$G$1253,"NT"))) -> 0.397 | G18: =IF($B18<>"OK","",IF(Eingaben!$B$5="Report",Reportdaten!G18,SUMIFS(Intervalle!$C$1158:$C$1253,Intervalle!$F$1158:$F$1253,"STANDARD",Intervalle!$G$1158:$G$1253,"ST"))) -> 0.137 | H18: =IF($B18<>"OK","",IF(Eingaben!$B$5="Report",Reportdaten!H18,SUMIFS(Intervalle!$C$1158:$C$1253,Intervalle!$F$1158:$F$1253,"STANDARD",Intervalle!$G$1158:$G$1253,"HT"))) -> 0.028 | I18: =IF($B18<>"OK","",IF(Eingaben!$B$5="Report",Reportdaten!I18,SUMIFS(Intervalle!$C$1158:$C$1253,Intervalle!$F$1158:$F$1253,"HEAT",Intervalle!$G$1158:$G$1253,"NT"))) -> 0 | J18: =IF($B18<>"OK","",IF(Eingaben!$B$5="Report",Reportdaten!J18,SUMIFS(Intervalle!$C$1158:$C$1253,Intervalle!$F$1158:$F$1253,"HEAT",Intervalle!$G$1158:$G$1253,"ST"))) -> 0 | K18: =IF($B18<>"OK","",IF(Eingaben!$B$5="Report",Reportdaten!K18,SUMIFS(Intervalle!$C$1158:$C$1253,Intervalle!$F$1158:$F$1253,"HEAT",Intervalle!$G$1158:$G$1253,"HT"))) -> 0 | L18: =IF($B18<>"OK","",SUM(C18:K18)) -> 0.632 | M18: =IF($B18<>"OK","",SUM(C18:E18)) -> 0.07 | N18: =IF($B18<>"OK","",SUM(F18:H18)) -> 0.562 | O18: =IF($B18<>"OK","",SUM(I18:K18)) -> 0 | P18: =IF($B18<>"OK","",C18+F18+I18) -> 0.467 | Q18: =IF($B18<>"OK","",D18+G18+J18) -> 0.137 | R18: =IF($B18<>"OK","",E18+H18+K18) -> 0.028 | S18: =IF($B18<>"OK","",M18*Eingaben!$B$11/100) -> 0.01054578 | T18: =IF($B18<>"OK","",N18*Eingaben!$B$12/100) -> 0.15890213 | U18: =IF($B18<>"OK","",IF(O18=0,0,O18*Eingaben!$B$13/100)) -> 0 | V18: =IF($B18<>"OK","",IF(Eingaben!$B$15="Zeitanteilig",Eingaben!$B$14*12/365,Eingaben!$B$14/Eingaben!$B$25)) -> 0.58352384 | W18: =IF($B18<>"OK","",L18*(IF(A18<Eingaben!$B$18,Eingaben!$B$9,Eingaben!$B$10)-Eingaben!$B$8)*(1+Eingaben!$B$7)/100) -> 0 | X18: =IF($B18<>"OK","",IF(A18>=Eingaben!$B$17,-Eingaben!$B$16*(1+Eingaben!$B$7)/Eingaben!$B$26,0)) -> -0.35318548 | Y18: =IF($B18<>"OK","",-L18*IF(A18<Eingaben!$B$18,Eingaben!$B$9,Eingaben!$B$10)*(1+Eingaben!$B$7)/100) -> -0.05753412 | Z18: =IF($B18<>"OK","",IF(A18<Eingaben!$B$18,P18*Eingaben!$B$9/100,IF(Eingaben!$B$5="Report",P18*Eingaben!$B$30/100,SUMIFS(Intervalle!$K$1158:$K$1253,Intervalle!$G$1158:$G$1253,"NT")))*(1+Eingaben!$B$7)) -> 0.009113972 | AA18: =IF($B18<>"OK","",IF(A18<Eingaben!$B$18,Q18*Eingaben!$B$9/100,IF(Eingaben!$B$5="Report",Q18*Eingaben!$B$31/100,SUMIFS(Intervalle!$K$1158:$K$1253,Intervalle!$G$1158:$G$1253,"ST")))*(1+Eingaben!$B$7)) -> 0.008934044 | AB18: =IF($B18<>"OK","",IF(A18<Eingaben!$B$18,R18*Eingaben!$B$9/100,IF(Eingaben!$B$5="Report",R18*Eingaben!$B$32/100,SUMIFS(Intervalle!$K$1158:$K$1253,Intervalle!$G$1158:$G$1253,"HT")))*(1+Eingaben!$B$7)) -> 0.003505264 | AC18: =IF($B18<>"OK","",-SUM(Y18:AB18)) -> 0.03598084 | AD18: =IF($B18<>"OK","",SUM(S18:AB18)) -> 0.36380542 | AE18: =IF($B18<>"OK","",IF(Eingaben!$B$5="Report",Reportdaten!L18,"")) -> 0.36 | AF18: =IF($B18<>"OK","",IF(Eingaben!$B$5="Report",AD18-AE18,"")) -> 0.0038054242
